2025-07-14 14:07:35,714 ERROR: Exception on /admin/system_settings [GET] [in C:\Users\USER\AppData\Local\Programs\Python\Python313\Lib\site-packages\flask\app.py:875]
Traceback (most recent call last):
  File "C:\Users\USER\AppData\Local\Programs\Python\Python313\Lib\site-packages\flask\app.py", line 1511, in wsgi_app
    response = self.full_dispatch_request()
  File "C:\Users\USER\AppData\Local\Programs\Python\Python313\Lib\site-packages\flask\app.py", line 919, in full_dispatch_request
    rv = self.handle_user_exception(e)
  File "C:\Users\USER\AppData\Local\Programs\Python\Python313\Lib\site-packages\flask\app.py", line 917, in full_dispatch_request
    rv = self.dispatch_request()
  File "C:\Users\USER\AppData\Local\Programs\Python\Python313\Lib\site-packages\flask\app.py", line 902, in dispatch_request
    return self.ensure_sync(self.view_functions[rule.endpoint])(**view_args)  # type: ignore[no-any-return]
           ~~~~~~~~~~~~~~~~~~~~~~~~~~~~~~~~~~~~~~~~~~~~~~~~~~~~^^^^^^^^^^^^^
  File "C:\Users\USER\AppData\Local\Programs\Python\Python313\Lib\site-packages\flask_login\utils.py", line 290, in decorated_view
    return current_app.ensure_sync(func)(*args, **kwargs)
           ~~~~~~~~~~~~~~~~~~~~~~~~~~~~~^^^^^^^^^^^^^^^^^
  File "C:\Users\USER\migrations\lost-\app\admin.py", line 160, in system_settings
    return render_template('system_settings.html')
  File "C:\Users\USER\AppData\Local\Programs\Python\Python313\Lib\site-packages\flask\templating.py", line 149, in render_template
    template = app.jinja_env.get_or_select_template(template_name_or_list)
  File "C:\Users\USER\AppData\Local\Programs\Python\Python313\Lib\site-packages\jinja2\environment.py", line 1087, in get_or_select_template
    return self.get_template(template_name_or_list, parent, globals)
           ~~~~~~~~~~~~~~~~~^^^^^^^^^^^^^^^^^^^^^^^^^^^^^^^^^^^^^^^^
  File "C:\Users\USER\AppData\Local\Programs\Python\Python313\Lib\site-packages\jinja2\environment.py", line 1016, in get_template
    return self._load_template(name, globals)
           ~~~~~~~~~~~~~~~~~~~^^^^^^^^^^^^^^^
  File "C:\Users\USER\AppData\Local\Programs\Python\Python313\Lib\site-packages\jinja2\environment.py", line 975, in _load_template
    template = self.loader.load(self, name, self.make_globals(globals))
  File "C:\Users\USER\AppData\Local\Programs\Python\Python313\Lib\site-packages\jinja2\loaders.py", line 126, in load
    source, filename, uptodate = self.get_source(environment, name)
                                 ~~~~~~~~~~~~~~~^^^^^^^^^^^^^^^^^^^
  File "C:\Users\USER\AppData\Local\Programs\Python\Python313\Lib\site-packages\flask\templating.py", line 65, in get_source
    return self._get_source_fast(environment, template)
           ~~~~~~~~~~~~~~~~~~~~~^^^^^^^^^^^^^^^^^^^^^^^
  File "C:\Users\USER\AppData\Local\Programs\Python\Python313\Lib\site-packages\flask\templating.py", line 99, in _get_source_fast
    raise TemplateNotFound(template)
jinja2.exceptions.TemplateNotFound: system_settings.html
2025-07-14 14:07:50,744 ERROR: Exception on /admin/audit_logs [GET] [in C:\Users\USER\AppData\Local\Programs\Python\Python313\Lib\site-packages\flask\app.py:875]
Traceback (most recent call last):
  File "C:\Users\USER\AppData\Local\Programs\Python\Python313\Lib\site-packages\flask\app.py", line 1511, in wsgi_app
    response = self.full_dispatch_request()
  File "C:\Users\USER\AppData\Local\Programs\Python\Python313\Lib\site-packages\flask\app.py", line 919, in full_dispatch_request
    rv = self.handle_user_exception(e)
  File "C:\Users\USER\AppData\Local\Programs\Python\Python313\Lib\site-packages\flask\app.py", line 917, in full_dispatch_request
    rv = self.dispatch_request()
  File "C:\Users\USER\AppData\Local\Programs\Python\Python313\Lib\site-packages\flask\app.py", line 902, in dispatch_request
    return self.ensure_sync(self.view_functions[rule.endpoint])(**view_args)  # type: ignore[no-any-return]
           ~~~~~~~~~~~~~~~~~~~~~~~~~~~~~~~~~~~~~~~~~~~~~~~~~~~~^^^^^^^^^^^^^
  File "C:\Users\USER\AppData\Local\Programs\Python\Python313\Lib\site-packages\flask_login\utils.py", line 290, in decorated_view
    return current_app.ensure_sync(func)(*args, **kwargs)
           ~~~~~~~~~~~~~~~~~~~~~~~~~~~~~^^^^^^^^^^^^^^^^^
  File "C:\Users\USER\migrations\lost-\app\admin.py", line 151, in audit_logs
    return render_template('audit_logs.html', logs=logs)
  File "C:\Users\USER\AppData\Local\Programs\Python\Python313\Lib\site-packages\flask\templating.py", line 150, in render_template
    return _render(app, template, context)
  File "C:\Users\USER\AppData\Local\Programs\Python\Python313\Lib\site-packages\flask\templating.py", line 131, in _render
    rv = template.render(context)
  File "C:\Users\USER\AppData\Local\Programs\Python\Python313\Lib\site-packages\jinja2\environment.py", line 1295, in render
    self.environment.handle_exception()
    ~~~~~~~~~~~~~~~~~~~~~~~~~~~~~~~~~^^
  File "C:\Users\USER\AppData\Local\Programs\Python\Python313\Lib\site-packages\jinja2\environment.py", line 942, in handle_exception
    raise rewrite_traceback_stack(source=source)
  File "C:\Users\USER\migrations\lost-\app\templates\audit_logs.html", line 1, in top-level template code
    {% extends "base.html" %}
  File "C:\Users\USER\migrations\lost-\app\templates\base.html", line 104, in top-level template code
    {% block content %}{% endblock %}
    ^^^^^^^^^^^^^^^^^
  File "C:\Users\USER\migrations\lost-\app\templates\audit_logs.html", line 62, in block 'content'
    {% for page_num in logs.iter_pages(left_edge=1, right_edge=1, left_current=2, right_current=2) %}
    ^^^^^^^^^
  File "C:\Users\USER\AppData\Local\Programs\Python\Python313\Lib\site-packages\jinja2\utils.py", line 92, in from_obj
    if hasattr(obj, "jinja_pass_arg"):
       ~~~~~~~^^^^^^^^^^^^^^^^^^^^^^^
jinja2.exceptions.UndefinedError: 'list object' has no attribute 'iter_pages'
2025-07-14 14:56:50,648 ERROR: Error loading PyTorch ResNet50 model: [WinError 10053] An established connection was aborted by the software in your host machine [in C:\Users\USER\migrations\lost-\app\image_matcher.py:41]
2025-07-14 14:56:50,813 WARNING: Could not extract features for image: fb9b7737-17ab-40ec-8dee-3bbcb3829827_download_6.jfif [in C:\Users\USER\migrations\lost-\app\routes.py:60]
2025-07-14 14:59:32,788 ERROR: Exception on /delete_item/2 [POST] [in C:\Users\USER\AppData\Local\Programs\Python\Python313\Lib\site-packages\flask\app.py:875]
Traceback (most recent call last):
  File "C:\Users\USER\AppData\Local\Programs\Python\Python313\Lib\site-packages\flask\app.py", line 1511, in wsgi_app
    response = self.full_dispatch_request()
  File "C:\Users\USER\AppData\Local\Programs\Python\Python313\Lib\site-packages\flask\app.py", line 919, in full_dispatch_request
    rv = self.handle_user_exception(e)
  File "C:\Users\USER\AppData\Local\Programs\Python\Python313\Lib\site-packages\flask\app.py", line 917, in full_dispatch_request
    rv = self.dispatch_request()
  File "C:\Users\USER\AppData\Local\Programs\Python\Python313\Lib\site-packages\flask\app.py", line 902, in dispatch_request
    return self.ensure_sync(self.view_functions[rule.endpoint])(**view_args)  # type: ignore[no-any-return]
           ~~~~~~~~~~~~~~~~~~~~~~~~~~~~~~~~~~~~~~~~~~~~~~~~~~~~^^^^^^^^^^^^^
  File "C:\Users\USER\AppData\Local\Programs\Python\Python313\Lib\site-packages\flask_login\utils.py", line 290, in decorated_view
    return current_app.ensure_sync(func)(*args, **kwargs)
           ~~~~~~~~~~~~~~~~~~~~~~~~~~~~~^^^^^^^^^^^^^^^^^
  File "C:\Users\USER\migrations\lost-\app\routes.py", line 444, in delete_item
    os.remove(image_path)
    ~~~~~~~~~^^^^^^^^^^^^
PermissionError: [WinError 32] The process cannot access the file because it is being used by another process: 'C:\\Users\\USER\\migrations\\lost-\\uploads\\0a8f90e3-e532-4d40-8517-e952888f6227_keys.jpg'
2025-07-14 14:59:44,313 ERROR: Exception on /delete_item/2 [POST] [in C:\Users\USER\AppData\Local\Programs\Python\Python313\Lib\site-packages\flask\app.py:875]
Traceback (most recent call last):
  File "C:\Users\USER\AppData\Local\Programs\Python\Python313\Lib\site-packages\flask\app.py", line 1511, in wsgi_app
    response = self.full_dispatch_request()
  File "C:\Users\USER\AppData\Local\Programs\Python\Python313\Lib\site-packages\flask\app.py", line 919, in full_dispatch_request
    rv = self.handle_user_exception(e)
  File "C:\Users\USER\AppData\Local\Programs\Python\Python313\Lib\site-packages\flask\app.py", line 917, in full_dispatch_request
    rv = self.dispatch_request()
  File "C:\Users\USER\AppData\Local\Programs\Python\Python313\Lib\site-packages\flask\app.py", line 902, in dispatch_request
    return self.ensure_sync(self.view_functions[rule.endpoint])(**view_args)  # type: ignore[no-any-return]
           ~~~~~~~~~~~~~~~~~~~~~~~~~~~~~~~~~~~~~~~~~~~~~~~~~~~~^^^^^^^^^^^^^
  File "C:\Users\USER\AppData\Local\Programs\Python\Python313\Lib\site-packages\flask_login\utils.py", line 290, in decorated_view
    return current_app.ensure_sync(func)(*args, **kwargs)
           ~~~~~~~~~~~~~~~~~~~~~~~~~~~~~^^^^^^^^^^^^^^^^^
  File "C:\Users\USER\migrations\lost-\app\routes.py", line 444, in delete_item
    os.remove(image_path)
    ~~~~~~~~~^^^^^^^^^^^^
PermissionError: [WinError 32] The process cannot access the file because it is being used by another process: 'C:\\Users\\USER\\migrations\\lost-\\uploads\\0a8f90e3-e532-4d40-8517-e952888f6227_keys.jpg'
